Workbook

Sheet Cover Page
D2: THE ANUP ENGINEERING LIMITED
B7: Integrated Financial Model • Forecasts & Equity Valuation
B10: ABOUT THE COMPANY
B11: The Anup Engineering Limited, part of the Lalbhai Group, is an Indian heavy-engineering company specializing in the design and fabrication of critical process equipment — including heat exchangers, reactors, pressure vessels and other custom-built equipment — for the oil & gas, refining, petrochemical, fertilizer and power sectors.
B16: TABLE OF CONTENTS
B17: 01 Income Statement | F17: 07 DCF Model
B18: 02 Balance Sheet | F18: 08 Peer Comparison
B19: 03 Cash Flow Statement | F19: 09 Peer Data
B20: 04 Revenue Segments | F20: 10 Beta
B21: 05 Graphical Representation | F21: 11 Risk Data
B22: 06 Estimate Sheet | F22: 12 Guidance
B24: COLOR KEY
C25: Hardcoded data / Actuals
C26: Formula / Cell links
C27: Assumptions / Drivers
B29: AUTHOR & MODEL INFORMATION
B30: Author | D30: Niranjan Desai
B31: Date | D31: 5 June 2026
B32: Purpose | D32: This forecasting financial model is prepared for academic and competition purposes.
B33: Description | D33: This model comprises proprietary formulas, logical structures and analytical frameworks created by the author for The Anup Engineering Limited (standalone entity).
B35: Acknowledgements | D35: Bloomberg (financial data); NMIMS (academic resources); and The Anup Engineering Limited annual reports & investor presentations.
B37: Contact | D37: +91 97699 87893
B38: Email (Personal) | D38: mr.niranjandesai@gmail.com
B39: Email (Academic) | D39: niranjan.desai553@nmims.in
B41: All figures in INR Crores (₹ Cr) unless stated. Disclaimer: This model is prepared for illustrative and educational purposes only and does not constitute investment advice or a recommendation to buy or sell any security.

Sheet Income Statement
B1: Anup Engineering Limited
B2: Fiscal year ending 31st Mar, 2026 | C2: H1 | D2: H2 | E2: FY | F2: H1 | G2: H2 | H2: FY | I2: H1 | J2: H2 | K2: FY | L2: H1 | M2: H2 | N2: FY | O2: H1 | P2: H2 | Q2: FY | R2: H1 | S2: H2 | T2: FY | U2: H1 | V2: H2 | W2: FY | X2: H1 | Y2: H2 | Z2: FY | AA2: H1 | AB2: H2 | AC2: FY | AD2: H1 | AE2: H2 | AF2: FY | AG2: H1 | AH2: H2 | AI2: FY
B3: All amounts in ₹ crores except per share data | C3: 2021 | D3: 2021 | E3: 2021 | F3: 2022 | G3: 2022 | H3: 2022 | I3: 2023 | J3: 2023 | K3: 2023 | L3: 2024 | M3: 2024 | N3: 2024 | O3: 2025 | P3: 2025 | Q3: 2025 | R3: 2026 | S3: 2026 | T3: 2026 | U3: 2027 E | V3: 2027 E | W3: 2027 E | X3: 2028 E | Y3: 2028 E | Z3: 2028 E | AA3: 2029 E | AB3: 2029 E | AC3: 2029 E | AD3: 2030 E | AE3: 2030 E | AF3: 2030 E | AG3: 2031 E | AH3: 2031 E | AI3: 2031 E
B5: INCOME STATEMENT
B7: Income
B8: Revenue from operations | C8: 116.8959 | D8: =E8-C8 | E8: 279.1296 | F8: 141.0507 | G8: =H8-F8 | H8: 288.2416 | I8: 152.7418 | J8: =K8-I8 | K8: 411.3381 | L8: 265.0608 | M8: =N8-L8 | N8: 550.3845 | O8: 339.1337 | P8: =Q8-O8 | Q8: 732.786 | R8: 407.5122 | S8: =T8-R8 | T8: 822.2877 | U8: ='Revenue Segments'!U69 | V8: ='Revenue Segments'!V69 | W8: ='Revenue Segments'!W69 | X8: ='Revenue Segments'!X69 | Y8: ='Revenue Segments'!Y69 | Z8: ='Revenue Segments'!Z69 | AA8: ='Revenue Segments'!AA69 | AB8: ='Revenue Segments'!AB69 | ... AI8: ='Revenue Segments'!AI69
B9: Growth % | F9: =(F8-C8)/C8 | G9: =(G8-D8)/D8 | H9: =(H8-E8)/E8 | I9: =(I8-F8)/F8 | J9: =(J8-G8)/G8 | K9: =(K8-H8)/H8 | L9: =(L8-I8)/I8 | M9: =(M8-J8)/J8 | ... AI9: =(AI8-AF8)/AF8
B12: Cost of materials consumed | C12: 53.5332 | D12: =E12-C12 | E12: 140.3952 | F12: 69.5237 | G12: =H12-F12 | H12: 162.7251 | I12: 103.0964 | J12: =K12-I12 | K12: 233.208 | L12: 118.2643 | M12: =N12-L12 | N12: 271.6647 | O12: 201.7059 | P12: =Q12-O12 | Q12: 409.9813 | R12: 186.8596 | S12: =T12-R12 | T12: 374.8979
B13: Changes in inventories | C13: 11.7919 | D13: =E13-C13 | E13: 7.6665 | F13: -2.8458 | G13: =H13-F13 | H13: -22.5585 | I13: -19.8119 | J13: =K13-I13 | K13: -11.3768 | L13: 21.0177 | M13: =N13-L13 | N13: 13.3156 | O13: -14.7911 | P13: =Q13-O13 | Q13: -12.3133 | R13: 4.9015 | S13: =T13-R13 | T13: 18.4005
B14: Cost of Goods Sold | C14: =C12+C13 | D14: =D12+D13 | E14: =E12+E13 | F14: =F12+F13 | G14: =G12+G13 | H14: =H12+H13 | I14: =I12+I13 | J14: =J12+J13 | ... T14: =T12+T13 | U14: =U8*U15 | V14: =V8*V15 | W14: =U14+V14 | X14: =X8*X15 | Y14: =Y8*Y15 | Z14: =X14+Y14 | AA14: =AA8*AA15 | AB14: =AB8*AB15 | AC14: =AA14+AB14 | AD14: =AD8*AD15 | AE14: =AE8*AE15 | AF14: =AD14+AE14 | AG14: =AG8*AG15 | AH14: =AH8*AH15 | AI14: =AG14+AH14
B15: As % of Sales | C15: =C14/C8 | D15: =D14/D8 | E15: =E14/E8 | F15: =F14/F8 | G15: =G14/G8 | H15: =H14/H8 | I15: =I14/I8 | J15: =J14/J8 | ... T15: =T14/T8 | U15: 0.48 | V15: =U15 | W15: =W14/W8 | X15: 0.48 | Y15: =X15 | Z15: =Z14/Z8 | AA15: 0.48 | AB15: =AA15 | AC15: =AC14/AC8 | AD15: =AB15-0.5% | AE15: =AD15 | AF15: =AF14/AF8 | AG15: =AE15-0.5% | AH15: =AG15 | AI15: =AI14/AI8
B17: Gross Profit | C17: =C8-C14 | D17: =D8-D14 | E17: =E8-E14 | F17: =F8-F14 | G17: =G8-G14 | H17: =H8-H14 | I17: =I8-I14 | J17: =J8-J14 | ... AI17: =AI8-AI14
B18: Gross Margin | C18: =C17/C8 | D18: =D17/D8 | E18: =E17/E8 | F18: =F17/F8 | G18: =G17/G8 | H18: =H17/H8 | I18: =I17/I8 | J18: =J17/J8 | ... AI18: =AI17/AI8
B20: Employee benefits expense | C20: 8.4449 | D20: =E20-C20 | E20: 17.3837 | F20: 11.1719 | G20: =H20-F20 | H20: 20.3548 | I20: 9.4939 | J20: =K20-I20 | K20: 20.9578 | L20: 15.5905 | M20: =N20-L20 | N20: 30.9611 | O20: 19.5635 | P20: =Q20-O20 | Q20: 41.8524 | R20: 25.2866 | S20: =T20-R20 | T20: 51.2752 | U20: =U8*U21 | V20: =V8*V21 | W20: =U20+V20 | X20: =X8*X21 | Y20: =Y8*Y21 | Z20: =X20+Y20 | AA20: =AA8*AA21 | AB20: =AB8*AB21 | AC20: =AA20+AB20 | AD20: =AD8*AD21 | AE20: =AE8*AE21 | AF20: =AD20+AE20 | AG20: =AG8*AG21 | AH20: =AH8*AH21 | AI20: =AG20+AH20
B21: As % of Sales | C21: =C20/C8 | D21: =D20/D8 | E21: =E20/E8 | F21: =F20/F8 | G21: =G20/G8 | H21: =H20/H8 | I21: =I20/I8 | J21: =J20/J8 | ... T21: =T20/T8 | U21: 0.058 | V21: =U21 | W21: =W20/W8 | X21: =V21 | Y21: =X21 | Z21: =Z20/Z8 | AA21: =Y21 | AB21: =AA21 | AC21: =AC20/AC8 | AD21: =AB21 | AE21: =AD21 | AF21: =AF20/AF8 | AG21: =AE21 | AH21: =AG21 | AI21: =AI20/AI8
B22: Other expenses | C22: 16.6056 | D22: =E22-C22 | E22: 44.9232 | F22: 28.0228 | G22: =H22-F22 | H22: 57.742 | I22: 30.0765 | J22: =K22-I22 | K22: 85.8442 | L22: 50.8185 | M22: =N22-L22 | N22: 107.6925 | O22: 56.3075 | P22: =Q22-O22 | Q22: 128.0416 | R22: 98.6367 | S22: =T22-R22 | T22: 203.5519 | U22: =U8*'Income Statement'!U58 | V22: =V8*'Income Statement'!V58 | W22: =U22+V22 | X22: =X8*'Income Statement'!X58 | Y22: =Y8*'Income Statement'!Y58 | Z22: =X22+Y22 | AA22: =AA8*'Income Statement'!AA58 | AB22: =AB8*'Income Statement'!AB58 | AC22: =AA22+AB22 | AD22: =AD8*'Income Statement'!AD58 | AE22: =AE8*'Income Statement'!AE58 | AF22: =AD22+AE22 | AG22: =AG8*'Income Statement'!AG58 | AH22: =AH8*'Income Statement'!AH58 | AI22: =AG22+AH22
B23: EBITDA | C23: =C17-SUM(C20,C22) | D23: =D17-SUM(D20,D22) | E23: =E17-SUM(E20,E22) | F23: =F17-SUM(F20,F22) | G23: =G17-SUM(G20,G22) | H23: =H17-SUM(H20,H22) | I23: =I17-SUM(I20,I22) | J23: =J17-SUM(J20,J22) | ... AI23: =AI17-SUM(AI20,AI22)
B24: EBITDA Margin | C24: =C23/C8 | D24: =D23/D8 | E24: =E23/E8 | F24: =F23/F8 | G24: =G23/G8 | H24: =H23/H8 | I24: =I23/I8 | J24: =J23/J8 | ... AI24: =AI23/AI8
B26: D&A Expenses | C26: 4.5149 | D26: =E26-C26 | E26: 10.5059 | F26: 5.7862 | G26: =H26-F26 | H26: 11.5922 | I26: 5.8629 | J26: =K26-I26 | K26: 12.5405 | L26: 7.0289 | M26: =N26-L26 | N26: 17.464 | O26: 11.3557 | P26: =Q26-O26 | Q26: 23.819 | R26: 13.2423 | S26: =T26-R26 | T26: 27.841 | U26: ='Balance Sheet'!U63 | V26: ='Balance Sheet'!V63 | W26: =U26+V26 | X26: ='Balance Sheet'!X63 | Y26: ='Balance Sheet'!Y63 | Z26: =X26+Y26 | AA26: ='Balance Sheet'!AA63 | AB26: ='Balance Sheet'!AB63 | AC26: =AA26+AB26 | AD26: ='Balance Sheet'!AD63 | AE26: ='Balance Sheet'!AE63 | AF26: =AD26+AE26 | AG26: ='Balance Sheet'!AG63 | AH26: ='Balance Sheet'!AH63 | AI26: =AG26+AH26
B27: EBIT/Operating Income | C27: =C23-C26 | D27: =D23-D26 | E27: =E23-E26 | F27: =F23-F26 | G27: =G23-G26 | H27: =H23-H26 | I27: =I23-I26 | J27: =J23-J26 | ... AI27: =AI23-AI26
B28: EBIT Margin | C28: =C27/C8 | D28: =D27/D8 | E28: =E27/E8 | F28: =F27/F8 | G28: =G27/G8 | H28: =H27/H8 | I28: =I27/I8 | J28: =J27/J8 | ... AI28: =AI27/AI8
B30: Other Income | C30: 1.5638 | D30: =E30-C30 | E30: 3.5543 | F30: 0.9833 | G30: =H30-F30 | H30: 3.7677 | I30: 0.6182 | J30: =K30-I30 | K30: 1.2421 | L30: 2.0524 | M30: =N30-L30 | N30: 9.0637 | O30: 3.9853 | P30: =Q30-O30 | Q30: 5.1341 | R30: 2.6912 | S30: =T30-R30 | T30: 1.6776 | U30: =T30 | V30: =U30 | W30: =U30+V30 | X30: =V30 | Y30: =X30 | Z30: =X30+Y30 | AA30: =Y30 | AB30: =AA30 | AC30: =AA30+AB30 | AD30: =AB30 | AE30: =AD30 | AF30: =AD30+AE30 | AG30: =AE30 | AH30: =AG30 | AI30: =AG30+AH30
B31: Finance Cost | C31: 0.2708 | D31: =E31-C31 | E31: 0.3444 | F31: 0.2223 | G31: =H31-F31 | H31: 1.0315 | I31: 0.5961 | J31: =K31-I31 | K31: 1.4083 | L31: 0.2067 | M31: =N31-L31 | N31: 2.1744 | O31: 1.9606 | P31: =Q31-O31 | Q31: 3.3389 | R31: 2.9776 | S31: =T31-R31 | T31: 8.6983 | U31: ='Income Statement'!U61 | V31: ='Income Statement'!V61 | W31: =U31+V31 | X31: ='Income Statement'!X61 | Y31: ='Income Statement'!Y61 | Z31: =X31+Y31 | AA31: ='Income Statement'!AA61 | AB31: ='Income Statement'!AB61 | AC31: =AA31+AB31 | AD31: ='Income Statement'!AD61 | AE31: ='Income Statement'!AE61 | AF31: =AD31+AE31 | AG31: ='Income Statement'!AG61 | AH31: ='Income Statement'!AH61 | AI31: =AG31+AH31
B32: PBT | C32: =C27+C30-C31 | D32: =D27+D30-D31 | E32: =E27+E30-E31 | F32: =F27+F30-F31 | G32: =G27+G30-G31 | H32: =H27+H30-H31 | I32: =I27+I30-I31 | J32: =J27+J30-J31 | ... AI32: =AI27+AI30-AI31
B33: PBT Margin | C33: =C32/C8 | D33: =D32/D8 | E33: =E32/E8 | F33: =F32/F8 | G33: =G32/G8 | H33: =H32/H8 | I33: =I32/I8 | J33: =J32/J8 | ... AI33: =AI32/AI8
B34: check | C34: 23.2984 | E34: 61.465 | F34: 30.1529 | H34: 61.1222 | I34: 24.0461 | K34: 69.9982 | L34: 54.1866 | N34: 116.1759 | O34: 67.0169 | Q34: 143.2002 | R34: 78.2991 | T34: 139.3005
B35: difference | C35: =C32-C34 | E35: =E32-E34 | F35: =F32-F34 | H35: =H32-H34 | I35: =I32-I34 | K35: =K32-K34 | L35: =L32-L34 | N35: =N32-N34 | O35: =O32-O34 | Q35: =Q32-Q34 | R35: =R32-R34 | T35: =T32-T34
B37: Tax Expense
B38: Current Tax | C38: 6.72 | D38: =E38-C38 | E38: 15.15 | F38: 7.13 | G38: =H38-F38 | H38: 15.45 | I38: 6.13 | J38: =K38-I38 | K38: 18.15 | L38: 14.04 | M38: =N38-L38 | N38: 26.5 | O38: 12.5596 | P38: =Q38-O38 | Q38: 30.0692 | R38: 20.4941 | S38: =T38-R38 | T38: 34.6886
B39: Earlier Years tax | C39: 0 | D39: =E39-C39 | E39: -6.916 | F39: 0 | G39: =H39-F39 | H39: -15.5737 | I39: 0 | J39: =K39-I39 | K39: 0 | L39: 0 | M39: =N39-L39 | N39: -14.5115 | O39: 0 | P39: =Q39-O39 | Q39: -3.4566 | R39: 0 | S39: =T39-R39 | T39: -5.3208
B40: Deferred Tax Charge/(Credit) | C40: -0.2848 | D40: =E40-C40 | E40: -0.2922 | F40: -0.6155 | G40: =H40-F40 | H40: -0.8085 | I40: -0.1702 | J40: =K40-I40 | K40: 0.4182 | L40: -0.1333 | M40: =N40-L40 | N40: 0.7124 | O40: -2.0961 | P40: =Q40-O40 | Q40: -1.7151 | R40: -0.5089 | S40: =T40-R40 | T40: -0.4597
B41: Total Tax Expense | C41: =SUM(C38:C40) | D41: =SUM(D38:D40) | E41: =SUM(E38:E40) | F41: =SUM(F38:F40) | G41: =SUM(G38:G40) | H41: =SUM(H38:H40) | I41: =SUM(I38:I40) | J41: =SUM(J38:J40) | ... T41: =SUM(T38:T40) | U41: =U32*U62 | V41: =V32*V62 | W41: =U41+V41 | X41: =X32*X62 | Y41: =Y32*Y62 | Z41: =X41+Y41 | AA41: =AA32*AA62 | AB41: =AB32*AB62 | AC41: =AA41+AB41 | AD41: =AD32*AD62 | AE41: =AE32*AE62 | AF41: =AD41+AE41 | AG41: =AG32*AG62 | AH41: =AH32*AH62 | AI41: =AG41+AH41
B43: PAT | C43: =C32-C41 | D43: =D32-D41 | E43: =E32-E41 | F43: =F32-F41 | G43: =G32-G41 | H43: =H32-H41 | I43: =I32-I41 | J43: =J32-J41 | ... AI43: =AI32-AI41
B44: check | C44: 16.8632 | E44: 53.5232 | F44: 23.6384 | H44: 62.0544 | I44: 18.0863 | K44: 51.43 | L44: 40.2799 | N44: 103.475 | O44: 56.5534 | Q44: 118.3027 | R44: 58.3139 | T44: 110.3924
B45: difference | C45: =C43-C44 | E45: =E43-E44 | F45: =F43-F44 | H45: =H43-H44 | I45: =I43-I44 | K45: =K43-K44 | L45: =L43-L44 | N45: =N43-N44 | O45: =O43-O44 | Q45: =Q43-Q44 | R45: =R43-R44 | T45: =T43-T44
B46: PAT Margin | C46: =C43/C8 | D46: =D43/D8 | E46: =E43/E8 | F46: =F43/F8 | G46: =G43/G8 | H46: =H43/H8 | I46: =I43/I8 | J46: =J43/J8 | ... AI46: =AI43/AI8
B48: Outstanding Shares (in crores) | C48: 2.00025 | D48: 2.00025 | E48: 2.00025 | F48: 2.00025 | G48: 2.00025 | H48: 2.00025 | I48: 2.00025 | J48: 2.00025 | K48: 2.00025 | L48: 2.00025 | M48: 2.00025 | N48: 2.00025 | O48: 2.00025 | P48: 2.00265 | Q48: 2.00265 | R48: 2.00265 | S48: 2.00315 | T48: 2.00315 | U48: =T48 | V48: =U48 | W48: =V48 | X48: =W48 | Y48: =X48 | Z48: =Y48 | AA48: =Z48 | AB48: =AA48 | ... AI48: =AH48
B49: EPS | C49: =C43/C48 | D49: =D43/D48 | E49: =E43/E48 | F49: =F43/F48 | G49: =G43/G48 | H49: =H43/H48 | I49: =I43/I48 | J49: =J43/J48 | ... AI49: =AI43/AI48
B50: MPS | C50: 275.15 | D50: 331.9 | E50: 331.9 | F50: 505.85 | G50: 400.45 | H50: 400.45 | I50: 424.93 | J50: 699.45 | K50: 699.45 | L50: 1196.93 | M50: 1949.25 | N50: 1949.25 | O50: 3148.85 | P50: 2991.2 | Q50: 2991.2 | R50: 2447.3 | S50: 1840.1 | T50: 1840.1
B51: Market Cap | C51: =C48*C50 | D51: =D48*D50 | E51: =E48*E50 | F51: =F48*F50 | G51: =G48*G50 | H51: =H48*H50 | I51: =I48*I50 | J51: =J48*J50 | ... T51: =T48*T50
...

Sheet Balance Sheet
B1: Anup Engineering Limited
B2: Fiscal year ending 31st Mar, 2026 | C2: H1 | D2: H2 | E2: FY | F2: H1 | G2: H2 | H2: FY | I2: H1 | J2: H2 | K2: FY | L2: H1 | M2: H2 | N2: FY | O2: H1 | P2: H2 | Q2: FY | R2: H1 | S2: H2 | T2: FY | U2: H1 | V2: H2 | W2: FY | X2: H1 | Y2: H2 | Z2: FY | AA2: H1 | AB2: H2 | AC2: FY | AD2: H1 | AE2: H2 | AF2: FY | AG2: H1 | AH2: H2 | AI2: FY
B3: All amounts in ₹ crores except per share data | C3: 2021 | D3: 2021 | E3: 2021 | F3: 2022 | G3: 2022 | H3: 2022 | I3: 2023 | J3: 2023 | K3: 2023 | L3: 2024 | M3: 2024 | N3: 2024 | O3: 2025 | P3: 2025 | Q3: 2025 | R3: 2026 | S3: 2026 | T3: 2026 | U3: 2027 E | V3: 2027 E | W3: 2027 E | X3: 2028 E | Y3: 2028 E | Z3: 2028 E | AA3: 2029 E | AB3: 2029 E | AC3: 2029 E | AD3: 2030 E | AE3: 2030 E | AF3: 2030 E | AG3: 2031 E | AH3: 2031 E | AI3: 2031 E
B5: BALANCE SHEET
B7: EQUITY AND LIABILITIES
B9: Equity Share Capital | C9: 10.2082 | D9: =E9 | E9: 9.8312 | F9: 9.8812 | G9: =H9 | H9: 9.8812 | I9: 9.8812 | J9: =K9 | K9: 9.8962 | L9: 9.9112 | M9: =N9 | N9: 9.9505 | O9: 20.0025 | P9: =Q9 | Q9: 20.0265 | R9: 20.0265 | S9: =T9 | T9: 20.0315 | U9: =T9 | V9: =U9 | W9: =V9 | X9: =W9 | Y9: =X9 | Z9: =Y9 | AA9: =Z9 | AB9: =AA9 | ... AI9: =AH9
B10: Other Equity | C10: 322.8136 | D10: =E10 | E10: 327.3179 | F10: 344.8998 | G10: =H10 | H10: 383.5297 | I10: 393.916 | J10: =K10 | K10: 427.7846 | L10: 454.2219 | M10: =N10 | N10: 518.4959 | O10: 528.4494 | P10: =Q10 | Q10: 591.9316 | R10: 616.2312 | S10: =T10 | T10: 670.975 | U10: =T10+'Income Statement'!U43-'Income Statement'!U56 | V10: =U10+'Income Statement'!V43-'Income Statement'!V56 | W10: =V10 | X10: =W10+'Income Statement'!X43-'Income Statement'!X56 | Y10: =X10+'Income Statement'!Y43-'Income Statement'!Y56 | Z10: =Y10 | AA10: =Z10+'Income Statement'!AA43-'Income Statement'!AA56 | AB10: =AA10+'Income Statement'!AB43-'Income Statement'!AB56 | AC10: =AB10 | AD10: =AC10+'Income Statement'!AD43-'Income Statement'!AD56 | AE10: =AD10+'Income Statement'!AE43-'Income Statement'!AE56 | AF10: =AE10 | AG10: =AF10+'Income Statement'!AG43-'Income Statement'!AG56 | AH10: =AG10+'Income Statement'!AH43-'Income Statement'!AH56 | AI10: =AH10
B11: Total Equity | C11: =SUM(C9:C10) | D11: =SUM(D9:D10) | E11: =SUM(E9:E10) | F11: =SUM(F9:F10) | G11: =SUM(G9:G10) | H11: =SUM(H9:H10) | I11: =SUM(I9:I10) | J11: =SUM(J9:J10) | ... AI11: =SUM(AI9:AI10)
B13: Borrowings | D13: =E13 | E13: 0 | F13: 0 | G13: =H13 | H13: 0 | I13: 0 | J13: =K13 | K13: 30.0254 | L13: 33.5767 | M13: =N13 | N13: 13.79 | O13: 12.2239 | P13: =Q13 | Q13: 8.239 | R13: 5.5299 | S13: =T13 | T13: 33.9215 | U13: =T13 | V13: =U13 | W13: =V13 | X13: =W13 | Y13: =X13 | Z13: =Y13 | AA13: =Z13 | AB13: =AA13 | ... AI13: =AH13
B14: Lease Liabilities | D14: =E14 | E14: 0 | F14: 0 | G14: =H14 | H14: 0 | I14: 0 | J14: =K14 | K14: 0 | L14: 0 | M14: =N14 | N14: 0.8413 | O14: 0.7468 | P14: =Q14 | Q14: 2.6527 | R14: 2.4898 | S14: =T14 | T14: 1.8778 | U14: =T14 | V14: =U14+3 | W14: =V14 | X14: =W14 | Y14: =X14 | Z14: =Y14 | AA14: =Z14 | AB14: =AA14 | AC14: =AB14 | AD14: =AC14 | ... AI14: =AH14
B15: Long-Term Provisions | D15: =E15 | E15: 0.0853 | F15: 0.0853 | G15: =H15 | H15: 0.3343 | I15: 0.3343 | J15: =K15 | K15: 0 | L15: 0 | M15: =N15 | N15: 2.3987 | O15: 10.7958 | P15: =Q15 | Q15: 5.7768 | R15: 6.7926 | S15: =T15 | T15: 5.9837 | U15: =T15 | V15: =U15 | W15: =V15 | X15: =W15 | Y15: =X15 | Z15: =Y15 | AA15: =Z15 | AB15: =AA15 | ... AI15: =AH15
B16: Deferred Tax Liabilities (Net) | C16: 14.779 | D16: =E16 | E16: 12.4736 | F16: 11.8548 | G16: =H16 | H16: 11.6506 | I16: 11.4732 | J16: =K16 | K16: 12.0978 | L16: 11.9616 | M16: =N16 | N16: 12.4492 | O16: 4.4934 | P16: =Q16 | Q16: 10.9749 | R16: 9.8801 | S16: =T16 | T16: 9.6979 | U16: =T16 | V16: =U16 | W16: =V16 | X16: =W16 | Y16: =X16 | Z16: =Y16 | AA16: =Z16 | AB16: =AA16 | ... AI16: =AH16
B17: Total Non-Current Liabilities | C17: =SUM(C13:C16) | D17: =SUM(D13:D16) | E17: =SUM(E13:E16) | F17: =SUM(F13:F16) | G17: =SUM(G13:G16) | H17: =SUM(H13:H16) | I17: =SUM(I13:I16) | J17: =SUM(J13:J16) | ... AI17: =SUM(AI13:AI16)
B19: Borrowings | D19: =E19 | E19: 0 | F19: 0 | G19: =H19 | H19: 0 | I19: 0 | J19: =K19 | K19: 4.3151 | L19: 11.2523 | M19: =N19 | N19: 5.4836 | O19: 5.6648 | P19: =Q19 | Q19: 21.2021 | R19: 149.3251 | S19: =T19 | T19: 73.88 | U19: =T19 | V19: 70 | W19: =V19 | X19: 65 | Y19: 60 | Z19: =Y19 | AA19: 55 | AB19: 50 | AC19: =AB19 | AD19: 45 | AE19: 40 | AF19: =AE19 | AG19: 35 | AH19: =AI19 | AI19: 30
B20: Lease Liabilities | D20: =E20 | E20: 0 | F20: 0 | G20: =H20 | H20: 0 | I20: 0 | J20: =K20 | K20: 0 | L20: 0 | M20: =N20 | N20: 0.1648 | O20: 0.182 | P20: =Q20 | Q20: 0.3237 | R20: 0.3322 | S20: =T20 | T20: 0.2082 | U20: =T20 | V20: =U20 | W20: =V20 | X20: =W20 | Y20: =X20 | Z20: =Y20 | AA20: =Z20 | AB20: =AA20 | ... AI20: =AH20
B21: Total O/S Dues Of Micro & Small Enterprises | D21: =E21 | E21: 0 | F21: 0 | G21: =H21 | H21: 0.3085 | I21: 0.0212 | J21: =K21 | K21: 0.6245 | L21: 3.0258 | M21: =N21 | N21: 13.2798 | O21: 15.4792 | P21: =Q21 | Q21: 29.6007 | R21: 31.8155 | S21: =T21 | T21: 29.9151 | W21: =V21 | Z21: =Y21 | AC21: =AB21 | AF21: =AE21 | AI21: =AH21
B22: Total O/S Dues Of Creditors Other Than Micro & Small Enterprises | C22: 28.3611 | D22: =E22 | E22: 26.9466 | F22: 30.8222 | G22: =H22 | H22: 42.9866 | I22: 40.7457 | J22: =K22 | K22: 65.2005 | L22: 38.0974 | M22: =N22 | N22: 49.6379 | O22: 66.4714 | P22: =Q22 | Q22: 58.8133 | R22: 48.9036 | S22: =T22 | T22: 55.0838 | W22: =V22 | Z22: =Y22 | AC22: =AB22 | AF22: =AE22 | AI22: =AH22
B23: Total Trade Payables | C23: =SUM(C21:C22) | D23: =SUM(D21:D22) | E23: =SUM(E21:E22) | F23: =SUM(F21:F22) | G23: =SUM(G21:G22) | H23: =SUM(H21:H22) | I23: =SUM(I21:I22) | J23: =SUM(J21:J22) | ... T23: =SUM(T21:T22) | U23: ='Balance Sheet'!U71/365*('Income Statement'!U14+'Income Statement'!S14) | V23: ='Balance Sheet'!V71/365*('Income Statement'!V14+'Income Statement'!U14) | W23: =V23 | X23: ='Balance Sheet'!X71/365*('Income Statement'!X14+'Income Statement'!V14) | Y23: ='Balance Sheet'!Y71/365*('Income Statement'!Y14+'Income Statement'!X14) | Z23: =Y23 | AA23: ='Balance Sheet'!AA71/365*('Income Statement'!AA14+'Income Statement'!Y14) | AB23: ='Balance Sheet'!AB71/365*('Income Statement'!AB14+'Income Statement'!AA14) | AC23: =AB23 | AD23: ='Balance Sheet'!AD71/365*('Income Statement'!AD14+'Income Statement'!AB14) | AE23: ='Balance Sheet'!AE71/365*('Income Statement'!AE14+'Income Statement'!AD14) | AF23: =AE23 | AG23: ='Balance Sheet'!AG71/365*('Income Statement'!AG14+'Income Statement'!AE14) | AH23: ='Balance Sheet'!AH71/365*('Income Statement'!AH14+'Income Statement'!AG14) | AI23: =AH23
B24: Other Financial Liabilities | C24: 8.0253 | D24: =E24 | E24: 2.494 | F24: 2.7014 | G24: =H24 | H24: 2.6483 | I24: 5.5005 | J24: =K24 | K24: 3.8477 | L24: 3.3442 | M24: =N24 | N24: 8.6134 | O24: 8.0072 | P24: =Q24 | Q24: 11.3576 | R24: 14.9178 | S24: =T24 | T24: 23.0812 | U24: =U72*('Income Statement'!U8+'Income Statement'!S8) | V24: =V72*('Income Statement'!V8+'Income Statement'!U8) | W24: =V24 | X24: =X72*('Income Statement'!X8+'Income Statement'!V8) | Y24: =Y72*('Income Statement'!Y8+'Income Statement'!X8) | Z24: =Y24 | AA24: =AA72*('Income Statement'!AA8+'Income Statement'!Y8) | AB24: =AB72*('Income Statement'!AB8+'Income Statement'!AA8) | AC24: =AB24 | AD24: =AD72*('Income Statement'!AD8+'Income Statement'!AB8) | AE24: =AE72*('Income Statement'!AE8+'Income Statement'!AD8) | AF24: =AE24 | AG24: =AG72*('Income Statement'!AG8+'Income Statement'!AE8) | AH24: =AH72*('Income Statement'!AH8+'Income Statement'!AG8) | AI24: =AH24
B25: Short-Term Provisions | C25: 1.126 | D25: =E25 | E25: 0.6224 | F25: 0.7514 | G25: =H25 | H25: 0.6365 | I25: 0.9358 | J25: =K25 | K25: 0.7389 | L25: 0.8229 | M25: =N25 | N25: 1.4338 | O25: 3.249 | P25: =Q25 | Q25: 2.5333 | R25: 3.1648 | S25: =T25 | T25: 3.8807 | U25: =U74*('Income Statement'!U8+'Income Statement'!S8) | V25: =V74*('Income Statement'!V8+'Income Statement'!U8) | W25: =V25 | X25: =X74*('Income Statement'!X8+'Income Statement'!V8) | Y25: =Y74*('Income Statement'!Y8+'Income Statement'!X8) | Z25: =Y25 | AA25: =AA74*('Income Statement'!AA8+'Income Statement'!Y8) | AB25: =AB74*('Income Statement'!AB8+'Income Statement'!AA8) | AC25: =AB25 | AD25: =AD74*('Income Statement'!AD8+'Income Statement'!AB8) | AE25: =AE74*('Income Statement'!AE8+'Income Statement'!AD8) | AF25: =AE25 | AG25: =AG74*('Income Statement'!AG8+'Income Statement'!AE8) | AH25: =AH74*('Income Statement'!AH8+'Income Statement'!AG8) | AI25: =AH25
B26: Other Current Liabilities | C26: 77.0848 | D26: =E26 | E26: 50.9509 | F26: 56.3176 | G26: =H26 | H26: 62.9655 | I26: 64.8595 | J26: =K26 | K26: 72.974 | L26: 101.3735 | M26: =N26 | N26: 154.5197 | O26: 177.7682 | P26: =Q26 | Q26: 144.0976 | R26: 62.1181 | S26: =T26 | T26: 24.8001 | U26: ='Balance Sheet'!U73*('Income Statement'!U8+'Income Statement'!S8) | V26: ='Balance Sheet'!V73*('Income Statement'!V$8+'Income Statement'!U$8) | W26: =V26 | X26: ='Balance Sheet'!X73*('Income Statement'!X8+'Income Statement'!V8) | Y26: ='Balance Sheet'!Y73*('Income Statement'!Y$8+'Income Statement'!X$8) | Z26: =Y26 | AA26: ='Balance Sheet'!AA73*('Income Statement'!AA8+'Income Statement'!Y8) | AB26: ='Balance Sheet'!AB73*('Income Statement'!AB$8+'Income Statement'!AA$8) | AC26: =AB26 | AD26: ='Balance Sheet'!AD73*('Income Statement'!AD8+'Income Statement'!AB8) | AE26: ='Balance Sheet'!AE73*('Income Statement'!AE$8+'Income Statement'!AD$8) | AF26: =AE26 | AG26: ='Balance Sheet'!AG73*('Income Statement'!AG8+'Income Statement'!AE8) | AH26: ='Balance Sheet'!AH73*('Income Statement'!AH$8+'Income Statement'!AG$8) | AI26: =AH26
B27: Current Tax Liabilities (Net) | D27: =E27 | E27: 0 | F27: 0 | G27: =H27 | H27: 10.3724 | I27: 10.3307 | J27: =K27 | K27: 15.4099 | L27: 20.5059 | M27: =N27 | N27: 17.3722 | O27: 18.4707 | P27: =Q27 | Q27: 18.6254 | R27: 25.352 | S27: =T27 | T27: 17.3227 | U27: =T27 | V27: =U27 | W27: =V27 | X27: =W27 | Y27: =X27 | Z27: =Y27 | AA27: =Z27 | AB27: =AA27 | ... AI27: =AH27
B28: Total Current Liabilities | C28: =SUM(C19:C20,C23:C27) | D28: =SUM(D19:D20,D23:D27) | E28: =SUM(E19:E20,E23:E27) | F28: =SUM(F19:F20,F23:F27) | G28: =SUM(G19:G20,G23:G27) | H28: =SUM(H19:H20,H23:H27) | I28: =SUM(I19:I20,I23:I27) | J28: =SUM(J19:J20,J23:J27) | ... AI28: =SUM(AI19:AI20,AI23:AI27)
B29: TOTAL EQUITY AND LIABILITIES | C29: =C11+C17+C28 | D29: =D11+D17+D28 | E29: =E11+E17+E28 | F29: =F11+F17+F28 | G29: =G11+G17+G28 | H29: =H11+H17+H28 | I29: =I11+I17+I28 | J29: =J11+J17+J28 | ... AI29: =AI11+AI17+AI28
B30: Check | C30: 462.398 | E30: 430.7219 | F30: 457.3137 | H30: 525.3136 | I30: 537.9981 | K30: 642.9146 | L30: 688.0934 | N30: 808.4308 | O30: 872.0043 | Q30: 926.1552 | R30: 996.8792 | T30: 970.6592
B31: Difference | C31: =C29-C30 | E31: =E29-E30 | F31: =F29-F30 | H31: =H29-H30 | I31: =I29-I30 | K31: =K29-K30 | L31: =L29-L30 | N31: =N29-N30 | O31: =O29-O30 | Q31: =Q29-Q30 | R31: =R29-R30 | T31: =T29-T30
B33: ASSETS
B35: Property, Plant And Equipment | C35: 181.3986 | D35: =E35 | E35: 188.0553 | F35: 185.1124 | G35: =H35 | H35: 182.9107 | I35: 193.3338 | J35: =K35 | K35: 200.6862 | L35: 294.2455 | M35: =N35 | N35: 299.5435 | O35: 322.9711 | P35: =Q35 | Q35: 288.0958 | R35: 314.2222 | S35: =T35 | T35: 328.3049 | U35: ='Balance Sheet'!U65 | V35: ='Balance Sheet'!V65 | W35: =V35 | X35: ='Balance Sheet'!X65 | Y35: ='Balance Sheet'!Y65 | Z35: =Y35 | AA35: ='Balance Sheet'!AA65 | AB35: ='Balance Sheet'!AB65 | AC35: =AB35 | AD35: ='Balance Sheet'!AD65 | AE35: ='Balance Sheet'!AE65 | AF35: =AE35 | AG35: ='Balance Sheet'!AG65 | AH35: ='Balance Sheet'!AH65 | AI35: =AH35
B36: Capital Work In Progress | C36: 7.61 | D36: =E36 | E36: 1.5337 | F36: 3.0925 | G36: =H36 | H36: 30.662 | I36: 59.2635 | J36: =K36 | K36: 87.0256 | L36: 7.9168 | M36: =N36 | N36: 15.5042 | O36: 14.5616 | P36: =Q36 | Q36: 9.9153 | R36: 14.598 | S36: =T36 | T36: 1.5728 | U36: 5 | V36: =U36 | W36: =V36 | X36: =W36 | Y36: =X36 | Z36: =Y36 | AA36: =Z36 | AB36: =AA36 | AC36: =AB36 | ... AI36: =AH36
B37: Goodwill On Consolidation | C37: 0 | D37: =E37 | E37: 0 | F37: 0 | G37: =H37 | H37: 0 | I37: 0 | J37: =K37 | K37: 0 | L37: 0 | M37: =N37 | N37: 0 | O37: 13.0164 | P37: =Q37 | Q37: 12.6164 | R37: 12.6164 | S37: =T37 | T37: 12.6164 | U37: =T37 | V37: =U37 | W37: =V37 | X37: =W37 | Y37: =X37 | Z37: =Y37 | AA37: =Z37 | AB37: =AA37 | ... AI37: =AH37
B38: Intangible Assets | C38: 25.3759 | D38: =E38 | E38: 23.72 | F38: 21.9603 | G38: =H38 | H38: 20.2005 | I38: 18.5722 | J38: =K38 | K38: 16.7009 | L38: 15.2288 | M38: =N38 | N38: 13.6719 | O38: 12.2365 | P38: =Q38 | Q38: 10.4086 | R38: 8.6507 | S38: =T38 | T38: 7.0597 | U38: =T38 | V38: =U38 | W38: =V38 | X38: =W38 | Y38: =X38 | Z38: =Y38 | AA38: =Z38 | AB38: =AA38 | ... AI38: =AH38
B39: Intangible Assets Under Development | C39: 0 | D39: =E39 | E39: 0 | F39: 0 | G39: =H39 | H39: 0 | I39: 0 | J39: =K39 | K39: 0 | L39: 0 | M39: =N39 | N39: 0.054 | O39: 0 | P39: =Q39 | Q39: 0 | R39: 0.1251 | S39: =T39 | T39: 0 | U39: =T39 | V39: =U39 | W39: =V39 | X39: =W39 | Y39: =X39 | Z39: =Y39 | AA39: =Z39 | AB39: =AA39 | ... AI39: =AH39
B40: Right Of Use Assets | C40: 0 | D40: =E40 | E40: 0 | F40: 0 | G40: =H40 | H40: 0 | I40: 0 | J40: =K40 | K40: 0 | L40: 0 | M40: =N40 | N40: 0 | O40: 0 | P40: =Q40 | Q40: 51.6565 | R40: 51.3151 | S40: =T40 | T40: 50.4817 | U40: =T40 | V40: =U40+(V14-U14) | W40: =V40 | X40: =W40 | Y40: =X40 | Z40: =Y40 | AA40: =Z40 | AB40: =AA40 | AC40: =AB40 | AD40: =AC40 | ... AI40: =AH40
B41: Other Financial Assets | C41: 0.7028 | D41: =E41 | E41: 0.733 | F41: 0.7572 | G41: =H41 | H41: 2.1833 | I41: 0.9294 | J41: =K41 | K41: 2.6321 | L41: 1.3199 | M41: =N41 | N41: 11.0554 | O41: 2.3295 | P41: =Q41 | Q41: 3.8095 | R41: 0.7194 | S41: =T41 | T41: 4.8304 | U41: =T41 | V41: =U41 | W41: =V41 | X41: =W41 | Y41: =X41 | Z41: =Y41 | AA41: =Z41 | AB41: =AA41 | ... AI41: =AH41
B42: Other Non-Current Assets | C42: 0.5876 | D42: =E42 | E42: 0.474 | F42: 0.4061 | G42: =H42 | H42: 9.8352 | I42: 4.623 | J42: =K42 | K42: 1.686 | L42: 1.1577 | M42: =N42 | N42: 3.827 | O42: 2.2817 | P42: =Q42 | Q42: 4.353 | R42: 0.6808 | S42: =T42 | T42: 1.3223 | U42: =T42 | V42: =U42 | W42: =V42 | X42: =W42 | Y42: =X42 | Z42: =Y42 | AA42: =Z42 | AB42: =AA42 | ... AI42: =AH42
B43: Total Non-Current Assets | C43: =SUM(C35:C42) | D43: =SUM(D35:D42) | E43: =SUM(E35:E42) | F43: =SUM(F35:F42) | G43: =SUM(G35:G42) | H43: =SUM(H35:H42) | I43: =SUM(I35:I42) | J43: =SUM(J35:J42) | ... AI43: =SUM(AI35:AI42)
B45: Inventories | C45: 85.1764 | D45: =E45 | E45: 66.7802 | F45: 64.4496 | G45: =H45 | H45: 90.1969 | I45: 115.8315 | J45: =K45 | K45: 126.9184 | L45: 118.9629 | M45: =N45 | N45: 165.2845 | O45: 179.6863 | P45: =Q45 | Q45: 147.2944 | R45: 148.3081 | S45: =T45 | T45: 100.7499 | U45: =('Income Statement'!U14+'Income Statement'!S14)/'Balance Sheet'!U76 | V45: =('Income Statement'!V14+'Income Statement'!U14)/'Balance Sheet'!V76 | W45: =V45 | X45: =('Income Statement'!X14+'Income Statement'!V14)/'Balance Sheet'!X76 | Y45: =('Income Statement'!Y14+'Income Statement'!X14)/'Balance Sheet'!Y76 | Z45: =Y45 | AA45: =('Income Statement'!AA14+'Income Statement'!Y14)/'Balance Sheet'!AA76 | AB45: =('Income Statement'!AB14+'Income Statement'!AA14)/'Balance Sheet'!AB76 | AC45: =AB45 | AD45: =('Income Statement'!AD14+'Income Statement'!AB14)/'Balance Sheet'!AD76 | AE45: =('Income Statement'!AE14+'Income Statement'!AD14)/'Balance Sheet'!AE76 | AF45: =AE45 | AG45: =('Income Statement'!AG14+'Income Statement'!AE14)/'Balance Sheet'!AG76 | AH45: =('Income Statement'!AH14+'Income Statement'!AG14)/'Balance Sheet'!AH76 | AI45: =AH45
B46: Financial Assets
B47: Investments | L47: 89.0044 | M47: =N47 | N47: 103.8624 | O47: 23.0281 | P47: =Q47 | Q47: 10.6319 | S47: =T47
B48: Trade Receivables | C48: 75.4486 | D48: =E48 | E48: 110.1157 | F48: 112.2841 | G48: =H48 | H48: 124.7955 | I48: 77.367 | J48: =K48 | K48: 148.5622 | L48: 127.2452 | M48: =N48 | N48: 127.2406 | O48: 228.9854 | P48: =Q48 | Q48: 283.6497 | R48: 350.4321 | S48: =T48 | T48: 415.9389 | U48: =('Income Statement'!U8+'Income Statement'!S8)/'Balance Sheet'!U78 | V48: =('Income Statement'!V8+'Income Statement'!U8)/'Balance Sheet'!V78 | W48: =V48 | X48: =('Income Statement'!X8+'Income Statement'!V8)/'Balance Sheet'!X78 | Y48: =('Income Statement'!Y8+'Income Statement'!X8)/'Balance Sheet'!Y78 | Z48: =Y48 | AA48: =('Income Statement'!AA8+'Income Statement'!Y8)/'Balance Sheet'!AA78 | AB48: =('Income Statement'!AB8+'Income Statement'!AA8)/'Balance Sheet'!AB78 | AC48: =AB48 | AD48: =('Income Statement'!AD8+'Income Statement'!AB8)/'Balance Sheet'!AD78 | AE48: =('Income Statement'!AE8+'Income Statement'!AD8)/'Balance Sheet'!AE78 | AF48: =AE48 | AG48: =('Income Statement'!AG8+'Income Statement'!AE8)/'Balance Sheet'!AG78 | AH48: =('Income Statement'!AH8+'Income Statement'!AG8)/'Balance Sheet'!AH78 | AI48: =AH48
...

Sheet Cash Flows
B1: Anup Engineering Limited
B2: Fiscal year ending 31st Mar, 2026 | C2: H1 | D2: H2 | E2: FY | F2: H1 | G2: H2 | H2: FY | I2: H1 | J2: H2 | K2: FY | L2: H1 | M2: H2 | N2: FY | O2: H1 | P2: H2 | Q2: FY | R2: H1 | S2: H2 | T2: FY | U2: H1 | V2: H2 | W2: FY | X2: H1 | Y2: H2 | Z2: FY | AA2: H1 | AB2: H2 | AC2: FY | AD2: H1 | AE2: H2 | AF2: FY | AG2: H1 | AH2: H2 | AI2: FY
B3: All amounts in ₹ crores except per share data | C3: 2021 | D3: 2021 | E3: 2021 | F3: 2022 | G3: 2022 | H3: 2022 | I3: 2023 | J3: 2023 | K3: 2023 | L3: 2024 | M3: 2024 | N3: 2024 | O3: 2025 | P3: 2025 | Q3: 2025 | R3: 2026 | S3: 2026 | T3: 2026 | U3: 2027 E | V3: 2027 E | W3: 2027 E | X3: 2028 E | Y3: 2028 E | Z3: 2028 E | AA3: 2029 E | AB3: 2029 E | AC3: 2029 E | AD3: 2030 E | AE3: 2030 E | AF3: 2030 E | AG3: 2031 E | AH3: 2031 E | AI3: 2031 E
B5: CASH FLOW STATEMENT
B7: Cash Flow from Operating Activities
B8: Profit Before Tax | C8: 23.2984 | D8: =E8-C8 | E8: 61.465 | F8: 30.1529 | G8: =H8-F8 | H8: 61.1222 | I8: 24.0461 | J8: =K8-I8 | K8: 69.9982 | L8: 54.1866 | M8: =N8-L8 | N8: 116.1759 | O8: 67.0169 | P8: =Q8-O8 | Q8: 143.2002 | R8: 78.2991 | S8: =T8-R8 | T8: 139.3005 | U8: ='Income Statement'!U32 | V8: ='Income Statement'!V32 | W8: =U8+V8 | X8: ='Income Statement'!X32 | Y8: ='Income Statement'!Y32 | Z8: =X8+Y8 | AA8: ='Income Statement'!AA32 | AB8: ='Income Statement'!AB32 | AC8: =AA8+AB8 | AD8: ='Income Statement'!AD32 | AE8: ='Income Statement'!AE32 | AF8: =AD8+AE8 | AG8: ='Income Statement'!AG32 | AH8: ='Income Statement'!AH32 | AI8: =AG8+AH8
B9: Adjustments for: | D9: =E9-C9 | E9: 0 | F9: 0 | G9: =H9-F9 | H9: 0 | I9: 0 | J9: =K9-I9 | K9: 0 | L9: 0 | M9: =N9-L9 | N9: 0 | O9: 0 | P9: =Q9-O9 | Q9: 0 | R9: 0 | S9: =T9-R9 | T9: 0 | W9: =U9+V9 | Z9: =X9+Y9 | AC9: =AA9+AB9 | AF9: =AD9+AE9 | AI9: =AG9+AH9
B10: Depreciation and Amortization expenses | C10: 4.5149 | D10: =E10-C10 | E10: 10.5059 | F10: 5.7862 | G10: =H10-F10 | H10: 11.5922 | I10: 5.8629 | J10: =K10-I10 | K10: 12.5405 | L10: 7.0289 | M10: =N10-L10 | N10: 17.464 | O10: 11.3557 | P10: =Q10-O10 | Q10: 23.819 | R10: 13.2423 | S10: =T10-R10 | T10: 27.841 | U10: ='Balance Sheet'!U63 | V10: ='Balance Sheet'!V63 | W10: =U10+V10 | X10: ='Balance Sheet'!X63 | Y10: ='Balance Sheet'!Y63 | Z10: =X10+Y10 | AA10: ='Balance Sheet'!AA63 | AB10: ='Balance Sheet'!AB63 | AC10: =AA10+AB10 | AD10: ='Balance Sheet'!AD63 | AE10: ='Balance Sheet'!AE63 | AF10: =AD10+AE10 | AG10: ='Balance Sheet'!AG63 | AH10: ='Balance Sheet'!AH63 | AI10: =AG10+AH10
B11: Addition/(Deductions) to Right to use Assets | C11: 0 | D11: 0 | E11: 0 | F11: 0 | G11: 0 | H11: 0 | I11: 0 | J11: 0 | K11: 0 | L11: 0 | M11: 0 | N11: 0 | O11: 0 | P11: 0 | Q11: 0 | R11: 0 | S11: 0 | T11: 0 | U11: ='Balance Sheet'!T40-'Balance Sheet'!U40 | V11: ='Balance Sheet'!U40-'Balance Sheet'!V40 | W11: =U11+V11 | X11: ='Balance Sheet'!W40-'Balance Sheet'!X40 | Y11: ='Balance Sheet'!X40-'Balance Sheet'!Y40 | Z11: =X11+Y11 | AA11: ='Balance Sheet'!Z40-'Balance Sheet'!AA40 | AB11: ='Balance Sheet'!AA40-'Balance Sheet'!AB40 | AC11: =AA11+AB11 | AD11: ='Balance Sheet'!AC40-'Balance Sheet'!AD40 | AE11: ='Balance Sheet'!AD40-'Balance Sheet'!AE40 | AF11: =AD11+AE11 | AG11: ='Balance Sheet'!AF40-'Balance Sheet'!AG40 | AH11: ='Balance Sheet'!AG40-'Balance Sheet'!AH40 | AI11: =AG11+AH11
B12: Increase/(Decrease) in Long term provisions | C12: 0 | D12: 0 | E12: 0 | F12: 0 | G12: 0 | H12: 0 | I12: 0 | J12: 0 | K12: 0 | L12: 0 | M12: 0 | N12: 0 | O12: 0 | P12: 0 | Q12: 0 | R12: 0 | S12: 0 | T12: 0 | U12: ='Balance Sheet'!U15-'Balance Sheet'!T15 | V12: ='Balance Sheet'!V15-'Balance Sheet'!U15 | W12: =U12+V12 | X12: ='Balance Sheet'!X15-'Balance Sheet'!W15 | Y12: ='Balance Sheet'!Y15-'Balance Sheet'!X15 | Z12: =X12+Y12 | AA12: ='Balance Sheet'!AA15-'Balance Sheet'!Z15 | AB12: ='Balance Sheet'!AB15-'Balance Sheet'!AA15 | AC12: =AA12+AB12 | AD12: ='Balance Sheet'!AD15-'Balance Sheet'!AC15 | AE12: ='Balance Sheet'!AE15-'Balance Sheet'!AD15 | AF12: =AD12+AE12 | AG12: ='Balance Sheet'!AG15-'Balance Sheet'!AF15 | AH12: ='Balance Sheet'!AH15-'Balance Sheet'!AG15 | AI12: =AG12+AH12
B13: Deferred Tax (Income)/Expense | C13: 0 | D13: 0 | E13: 0 | F13: 0 | G13: 0 | H13: 0 | I13: 0 | J13: 0 | K13: 0 | L13: 0 | M13: 0 | N13: 0 | O13: 0 | P13: 0 | Q13: 0 | R13: 0 | S13: 0 | T13: 0 | U13: ='Balance Sheet'!U16-'Balance Sheet'!T16 | V13: ='Balance Sheet'!V16-'Balance Sheet'!U16 | W13: =U13+V13 | X13: ='Balance Sheet'!X16-'Balance Sheet'!W16 | Y13: ='Balance Sheet'!Y16-'Balance Sheet'!X16 | Z13: =X13+Y13 | AA13: ='Balance Sheet'!AA16-'Balance Sheet'!Z16 | AB13: ='Balance Sheet'!AB16-'Balance Sheet'!AA16 | AC13: =AA13+AB13 | AD13: ='Balance Sheet'!AD16-'Balance Sheet'!AC16 | AE13: ='Balance Sheet'!AE16-'Balance Sheet'!AD16 | AF13: =AD13+AE13 | AG13: ='Balance Sheet'!AG16-'Balance Sheet'!AF16 | AH13: ='Balance Sheet'!AH16-'Balance Sheet'!AG16 | AI13: =AG13+AH13
B14: Interest income from financial assets measured at amortised cost | C14: -0.8366 | D14: =E14-C14 | E14: -2.0066 | F14: -0.8986 | G14: =H14-F14 | H14: -3.5992 | I14: -0.6182 | J14: =K14-I14 | K14: -0.9531 | L14: -0.0896 | M14: =N14-L14 | N14: -1.8442 | O14: -0.4494 | P14: =Q14-O14 | Q14: -0.89 | R14: -0.5536 | S14: =T14-R14 | T14: -0.8627 | W14: =U14+V14 | Z14: =X14+Y14 | AC14: =AA14+AB14 | AF14: =AD14+AE14 | AI14: =AG14+AH14
B15: Gain on sale of current investments | C15: -0.7108 | D15: =E15-C15 | E15: -0.7108 | F15: 0 | G15: =H15-F15 | H15: 0 | I15: 0 | J15: =K15-I15 | K15: 0 | L15: 0 | M15: =N15-L15 | N15: -2.8948 | O15: -2.6097 | P15: =Q15-O15 | Q15: -1.8109 | R15: -0.0777 | S15: =T15-R15 | T15: -0.1208 | W15: =U15+V15 | Z15: =X15+Y15 | AC15: =AA15+AB15 | AF15: =AD15+AE15 | AI15: =AG15+AH15
B16: Change in fair valuation of current investments | C16: 0 | D16: =E16-C16 | E16: 0 | F16: 0 | G16: =H16-F16 | H16: 0 | I16: 0 | J16: =K16-I16 | K16: 0 | L16: -1.4636 | M16: =N16-L16 | N16: -1.6486 | O16: 0.1398 | P16: =Q16-O16 | Q16: -1.196 | R16: 0 | S16: =T16-R16 | T16: 0 | W16: =U16+V16 | Z16: =X16+Y16 | AC16: =AA16+AB16 | AF16: =AD16+AE16 | AI16: =AG16+AH16
B17: Finance Costs | C17: 0.2708 | D17: =E17-C17 | E17: 0.3444 | F17: 0.2223 | G17: =H17-F17 | H17: 1.0315 | I17: 0.5961 | J17: =K17-I17 | K17: 1.4083 | L17: 0.2067 | M17: =N17-L17 | N17: 2.1744 | O17: 1.9606 | P17: =Q17-O17 | Q17: 3.3389 | R17: 2.9776 | S17: =T17-R17 | T17: 8.6983 | U17: ='Income Statement'!U31 | V17: ='Income Statement'!V31 | W17: =U17+V17 | X17: ='Income Statement'!X31 | Y17: ='Income Statement'!Y31 | Z17: =X17+Y17 | AA17: ='Income Statement'!AA31 | AB17: ='Income Statement'!AB31 | AC17: =AA17+AB17 | AD17: ='Income Statement'!AD31 | AE17: ='Income Statement'!AE31 | AF17: =AD17+AE17 | AG17: ='Income Statement'!AG31 | AH17: ='Income Statement'!AH31 | AI17: =AG17+AH17
B18: Allowance/(Reversal) for doubtful debts | C18: 1.4253 | D18: =E18-C18 | E18: 1.6853 | F18: 1.1071 | G18: =H18-F18 | H18: 1.8949 | I18: -1.0368 | J18: =K18-I18 | K18: -0.2126 | L18: -0.1986 | M18: =N18-L18 | N18: 2.5438 | O18: -0.1268 | P18: =Q18-O18 | Q18: 0.0154 | R18: 0.659 | S18: =T18-R18 | T18: 0.9183 | W18: =U18+V18 | Z18: =X18+Y18 | AC18: =AA18+AB18 | AF18: =AD18+AE18 | AI18: =AG18+AH18
B19: Remeasurement (Gain)/Loss on lease | T19: -0.0085
B20: Property, Plant & Equipment written off | C20: 0 | D20: =E20-C20 | E20: 0.355 | F20: 0 | G20: =H20-F20 | H20: 0 | I20: 0.0287 | J20: =K20-I20 | K20: 0.0771 | L20: 0 | M20: =N20-L20 | N20: 0 | O20: 0 | P20: =Q20-O20 | Q20: 0 | R20: 0 | S20: =T20-R20 | T20: 0 | W20: =U20+V20 | Z20: =X20+Y20 | AC20: =AA20+AB20 | AF20: =AD20+AE20 | AI20: =AG20+AH20
B21: Bad Debts Written off | C21: 0.0339 | D21: =E21-C21 | E21: 0.0339 | F21: 0 | G21: =H21-F21 | H21: 0 | I21: 0 | J21: =K21-I21 | K21: 0 | L21: 0 | M21: =N21-L21 | N21: 0 | O21: 0 | P21: =Q21-O21 | Q21: 0.0214 | R21: 0 | S21: =T21-R21 | T21: 0 | W21: =U21+V21 | Z21: =X21+Y21 | AC21: =AA21+AB21 | AF21: =AD21+AE21 | AI21: =AG21+AH21
B22: Sundry Debit/(Credit) Balances appropriated (Net) | C22: 0 | D22: =E22-C22 | E22: -0.7912 | F22: 0.0029 | G22: =H22-F22 | H22: -0.0715 | I22: 0 | J22: =K22-I22 | K22: -0.0764 | L22: 0 | M22: =N22-L22 | N22: 0.2386 | O22: 0.016 | P22: =Q22-O22 | Q22: -0.0017 | R22: 0.0006 | S22: =T22-R22 | T22: 0.0311 | W22: =U22+V22 | Z22: =X22+Y22 | AC22: =AA22+AB22 | AF22: =AD22+AE22 | AI22: =AG22+AH22
B23: (Profit)/Loss on sale of Property, Plant & Equipment and Intangible | C23: 0.0557 | D23: =E23-C23 | E23: 0.0637 | F23: -0.0069 | G23: =H23-F23 | H23: -0.0187 | I23: 0.0235 | J23: =K23-I23 | K23: 0.0383 | L23: -0.0685 | M23: =N23-L23 | N23: -0.1228 | O23: -0.3665 | P23: =Q23-O23 | Q23: -0.3846 | R23: 0.0124 | S23: =T23-R23 | T23: 0.037 | W23: =U23+V23 | Z23: =X23+Y23 | AC23: =AA23+AB23 | AF23: =AD23+AE23 | AI23: =AG23+AH23
B24: Unrealised gain on foreign exchange fluctuation (net) | C24: 0 | D24: =E24-C24 | E24: 0 | F24: 0 | G24: =H24-F24 | H24: 0 | I24: 0 | J24: =K24-I24 | K24: -0.2922 | L24: 0 | M24: =N24-L24 | N24: -1.095 | O24: 0 | P24: =Q24-O24 | Q24: -0.0912 | R24: 0 | S24: =T24-R24 | T24: -6.4154 | W24: =U24+V24 | Z24: =X24+Y24 | AC24: =AA24+AB24 | AF24: =AD24+AE24 | AI24: =AG24+AH24
B25: Provision for Warranty | C25: 0 | D25: =E25-C25 | E25: 0 | F25: 0 | G25: =H25-F25 | H25: 0 | I25: 0 | J25: =K25-I25 | K25: 0 | L25: 0 | M25: =N25-L25 | N25: 2 | O25: 0 | P25: =Q25-O25 | Q25: 0.5 | R25: 1 | S25: =T25-R25 | T25: 0 | W25: =U25+V25 | Z25: =X25+Y25 | AC25: =AA25+AB25 | AF25: =AD25+AE25 | AI25: =AG25+AH25
B26: Tax on Exceptional Item | T26: -0.4886
B27: Share based payment expense | C27: 0.2233 | D27: =E27-C27 | E27: 0.4455 | F27: 0.1422 | G27: =H27-F27 | H27: 0.3892 | I27: 0.2263 | J27: =K27-I27 | K27: 0.4313 | L27: 0.6567 | M27: =N27-L27 | N27: 1.4646 | O27: 1.3978 | P27: =Q27-O27 | Q27: 2.8123 | R27: 1.7697 | S27: =T27-R27 | T27: 3.6731 | W27: =U27+V27 | Z27: =X27+Y27 | AC27: =AA27+AB27 | AF27: =AD27+AE27 | AI27: =AG27+AH27
B29: Operating Cash flow before Working Capital Changes | C29: =SUM(C8:C28) | D29: =SUM(D8:D28) | E29: =SUM(E8:E28) | F29: =SUM(F8:F28) | G29: =SUM(G8:G28) | H29: =SUM(H8:H28) | I29: =SUM(I8:I28) | J29: =SUM(J8:J28) | ... AI29: =SUM(AI8:AI28)
B30: Adjustments for changes in working capital :
B31: (Increase)/Decrease in inventories | C31: 21.0053 | D31: =E31-C31 | E31: 39.4015 | F31: 2.3306 | G31: =H31-F31 | H31: -23.4167 | I31: -25.6346 | J31: =K31-I31 | K31: -36.7215 | L31: 7.9555 | M31: =N31-L31 | N31: -38.3661 | O31: -9.0219 | P31: =Q31-O31 | Q31: 23.37 | R31: -1.0137 | S31: =T31-R31 | T31: 46.5445 | U31: ='Balance Sheet'!T45-'Balance Sheet'!U45 | V31: ='Balance Sheet'!U45-'Balance Sheet'!V45 | W31: =U31+V31 | X31: ='Balance Sheet'!W45-'Balance Sheet'!X45 | Y31: ='Balance Sheet'!X45-'Balance Sheet'!Y45 | Z31: =SUM(X31:Y31) | AA31: ='Balance Sheet'!Z45-'Balance Sheet'!AA45 | AB31: ='Balance Sheet'!AA45-'Balance Sheet'!AB45 | AC31: =SUM(AA31:AB31) | AD31: ='Balance Sheet'!AC45-'Balance Sheet'!AD45 | AE31: ='Balance Sheet'!AD45-'Balance Sheet'!AE45 | AF31: =SUM(AD31:AE31) | AG31: ='Balance Sheet'!AF45-'Balance Sheet'!AG45 | AH31: ='Balance Sheet'!AG45-'Balance Sheet'!AH45 | AI31: =SUM(AG31:AH31)
B32: (Increase)/Decrease in trade receivables | C32: -12.5228 | D32: =E32-C32 | E32: -47.3927 | F32: -3.2583 | G32: =H32-F32 | H32: -16.5402 | I32: 48.4625 | J32: =K32-I32 | K32: -23.318 | L32: 21.4571 | M32: =N32-L32 | N32: 19.7854 | O32: -84.0345 | P32: =Q32-O32 | Q32: -138.857 | R32: -67.442 | S32: =T32-R32 | T32: -126.7835 | U32: ='Balance Sheet'!T48-'Balance Sheet'!U48 | V32: ='Balance Sheet'!U48-'Balance Sheet'!V48 | W32: =U32+V32 | X32: ='Balance Sheet'!W48-'Balance Sheet'!X48 | Y32: ='Balance Sheet'!X48-'Balance Sheet'!Y48 | Z32: ='Balance Sheet'!W48-'Balance Sheet'!Z48 | AA32: ='Balance Sheet'!Z48-'Balance Sheet'!AA48 | AB32: ='Balance Sheet'!AA48-'Balance Sheet'!AB48 | AC32: ='Balance Sheet'!Z48-'Balance Sheet'!AC48 | AD32: ='Balance Sheet'!AC48-'Balance Sheet'!AD48 | AE32: ='Balance Sheet'!AD48-'Balance Sheet'!AE48 | AF32: ='Balance Sheet'!AC48-'Balance Sheet'!AF48 | AG32: ='Balance Sheet'!AF48-'Balance Sheet'!AG48 | AH32: ='Balance Sheet'!AG48-'Balance Sheet'!AH48 | AI32: ='Balance Sheet'!AF48-'Balance Sheet'!AI48
B33: (Increase)/Decrease in other financial assets | C33: 10.6973 | D33: =E33-C33 | E33: -0.023 | F33: 2.559 | G33: =H33-F33 | H33: -0.1408 | I33: -20.6075 | J33: =K33-I33 | K33: -0.2143 | L33: 1.3122 | M33: =N33-L33 | N33: 0.4982 | O33: -1.3542 | P33: =Q33-O33 | Q33: -0.1357 | R33: 3.0901 | S33: =T33-R33 | T33: -1.0209 | U33: ='Balance Sheet'!T51-'Balance Sheet'!U51 | V33: ='Balance Sheet'!U51-'Balance Sheet'!V51 | W33: =U33+V33 | X33: ='Balance Sheet'!W51-'Balance Sheet'!X51 | Y33: ='Balance Sheet'!X51-'Balance Sheet'!Y51 | Z33: ='Balance Sheet'!W51-'Balance Sheet'!Z51 | AA33: ='Balance Sheet'!Z51-'Balance Sheet'!AA51 | AB33: ='Balance Sheet'!AA51-'Balance Sheet'!AB51 | AC33: ='Balance Sheet'!Z51-'Balance Sheet'!AC51 | AD33: ='Balance Sheet'!AC51-'Balance Sheet'!AD51 | AE33: ='Balance Sheet'!AD51-'Balance Sheet'!AE51 | AF33: ='Balance Sheet'!AC51-'Balance Sheet'!AF51 | AG33: ='Balance Sheet'!AF51-'Balance Sheet'!AG51 | AH33: ='Balance Sheet'!AG51-'Balance Sheet'!AH51 | AI33: ='Balance Sheet'!AF51-'Balance Sheet'!AI51
B34: (Increase)/Decrease in other assets | C34: -0.003 | D34: =E34-C34 | E34: 6.1475 | F34: -0.041 | G34: =H34-F34 | H34: -2.6011 | I34: 0.0036 | J34: =K34-I34 | K34: -13.1796 | L34: 10.5316 | M34: =N34-L34 | N34: -19.837 | O34: -18.0463 | P34: =Q34-O34 | Q34: -41.2285 | R34: 7.8807 | S34: =T34-R34 | T34: 52.7883 | U34: ='Balance Sheet'!T53-'Balance Sheet'!U53 | V34: ='Balance Sheet'!U53-'Balance Sheet'!V53 | W34: =U34+V34 | X34: ='Balance Sheet'!W53-'Balance Sheet'!X53 | Y34: ='Balance Sheet'!X53-'Balance Sheet'!Y53 | Z34: ='Balance Sheet'!W53-'Balance Sheet'!Z53 | AA34: ='Balance Sheet'!Z53-'Balance Sheet'!AA53 | AB34: ='Balance Sheet'!AA53-'Balance Sheet'!AB53 | AC34: ='Balance Sheet'!Z53-'Balance Sheet'!AC53 | AD34: ='Balance Sheet'!AC53-'Balance Sheet'!AD53 | AE34: ='Balance Sheet'!AD53-'Balance Sheet'!AE53 | AF34: ='Balance Sheet'!AC53-'Balance Sheet'!AF53 | AG34: ='Balance Sheet'!AF53-'Balance Sheet'!AG53 | AH34: ='Balance Sheet'!AG53-'Balance Sheet'!AH53 | AI34: ='Balance Sheet'!AF53-'Balance Sheet'!AI53
B35: Increase/(Decrease) in trade payables | C35: 5.1684 | D35: =E35-C35 | E35: 4.5451 | F35: 3.8756 | G35: =H35-F35 | H35: 16.42 | I35: -2.5282 | J35: =K35-I35 | K35: 22.6063 | L35: -24.7018 | M35: =N35-L35 | N35: -2.8986 | O35: 13.8164 | P35: =Q35-O35 | Q35: 21.484 | R35: -7.6949 | S35: =T35-R35 | T35: -3.4548 | U35: ='Balance Sheet'!U23-'Balance Sheet'!T23 | V35: ='Balance Sheet'!V23-'Balance Sheet'!U23 | W35: =U35+V35 | X35: =-('Balance Sheet'!W23-'Balance Sheet'!X23) | Y35: =-('Balance Sheet'!X23-'Balance Sheet'!Y23) | Z35: =-('Balance Sheet'!W23-'Balance Sheet'!Z23) | AA35: =-('Balance Sheet'!Z23-'Balance Sheet'!AA23) | AB35: =-('Balance Sheet'!AA23-'Balance Sheet'!AB23) | AC35: =-('Balance Sheet'!Z23-'Balance Sheet'!AC23) | AD35: =-('Balance Sheet'!AC23-'Balance Sheet'!AD23) | AE35: =-('Balance Sheet'!AD23-'Balance Sheet'!AE23) | AF35: =-('Balance Sheet'!AC23-'Balance Sheet'!AF23) | AG35: =-('Balance Sheet'!AF23-'Balance Sheet'!AG23) | AH35: =-('Balance Sheet'!AG23-'Balance Sheet'!AH23) | AI35: =-('Balance Sheet'!AF23-'Balance Sheet'!AI23)
B36: Increase/(Decrease) in other financial liabilities | C36: -1.1206 | D36: =E36-C36 | E36: 0.0786 | F36: 0.2074 | G36: =H36-F36 | H36: 0.056 | I36: 2.7611 | J36: =K36-I36 | K36: 1.1055 | L36: -0.7377 | M36: =N36-L36 | N36: 4.2963 | O36: -1.1073 | P36: =Q36-O36 | Q36: 1.5413 | R36: 0.9584 | S36: =T36-R36 | T36: 8.5584 | U36: ='Balance Sheet'!U24-'Balance Sheet'!T24 | V36: ='Balance Sheet'!V24-'Balance Sheet'!U24 | W36: =U36+V36 | X36: =-('Balance Sheet'!W24-'Balance Sheet'!X24) | Y36: =-('Balance Sheet'!X24-'Balance Sheet'!Y24) | Z36: =-('Balance Sheet'!W24-'Balance Sheet'!Z24) | AA36: =-('Balance Sheet'!Z24-'Balance Sheet'!AA24) | AB36: =-('Balance Sheet'!AA24-'Balance Sheet'!AB24) | AC36: =-('Balance Sheet'!Z24-'Balance Sheet'!AC24) | AD36: =-('Balance Sheet'!AC24-'Balance Sheet'!AD24) | AE36: =-('Balance Sheet'!AD24-'Balance Sheet'!AE24) | AF36: =-('Balance Sheet'!AC24-'Balance Sheet'!AF24) | AG36: =-('Balance Sheet'!AF24-'Balance Sheet'!AG24) | AH36: =-('Balance Sheet'!AG24-'Balance Sheet'!AH24) | AI36: =-('Balance Sheet'!AF24-'Balance Sheet'!AI24)
B37: Increase/(Decrease) in other current liabilities | C37: 19.087 | D37: =E37-C37 | E37: -8.6732 | F37: 5.3667 | G37: =H37-F37 | H37: 12.0146 | I37: 1.894 | J37: =K37-I37 | K37: 10.0085 | L37: 28.3995 | M37: =N37-L37 | N37: 81.5457 | O37: 17.7573 | P37: =Q37-O37 | Q37: -16.1041 | R37: -81.9795 | S37: =T37-R37 | T37: -119.2975 | U37: ='Balance Sheet'!U26-'Balance Sheet'!T26 | V37: ='Balance Sheet'!V26-'Balance Sheet'!U26 | W37: =U37+V37 | X37: =-('Balance Sheet'!W26-'Balance Sheet'!X26) | Y37: =-('Balance Sheet'!X26-'Balance Sheet'!Y26) | Z37: =-('Balance Sheet'!W26-'Balance Sheet'!Z26) | AA37: =-('Balance Sheet'!Z26-'Balance Sheet'!AA26) | AB37: =-('Balance Sheet'!AA26-'Balance Sheet'!AB26) | AC37: =-('Balance Sheet'!Z26-'Balance Sheet'!AC26) | AD37: =-('Balance Sheet'!AC26-'Balance Sheet'!AD26) | AE37: =-('Balance Sheet'!AD26-'Balance Sheet'!AE26) | AF37: =-('Balance Sheet'!AC26-'Balance Sheet'!AF26) | AG37: =-('Balance Sheet'!AF26-'Balance Sheet'!AG26) | AH37: =-('Balance Sheet'!AG26-'Balance Sheet'!AH26) | AI37: =-('Balance Sheet'!AF26-'Balance Sheet'!AI26)
B38: Increase/(Decrease) in provisions | C38: 0.181 | D38: =E38-C38 | E38: -0.1984 | F38: 0.1158 | G38: =H38-F38 | H38: 0.2054 | I38: 0.2705 | J38: =K38-I38 | K38: -0.1167 | L38: 0.1416 | M38: =N38-L38 | N38: -0.0693 | O38: 0.6493 | P38: =Q38-O38 | Q38: 1.69 | R38: 0.4431 | S38: =T38-R38 | T38: 2.8927 | U38: ='Balance Sheet'!U25-'Balance Sheet'!T25 | V38: ='Balance Sheet'!V25-'Balance Sheet'!U25 | W38: =U38+V38 | X38: =-('Balance Sheet'!W25-'Balance Sheet'!X25) | Y38: =-('Balance Sheet'!X25-'Balance Sheet'!Y25) | Z38: =-('Balance Sheet'!W25-'Balance Sheet'!Z25) | AA38: =-('Balance Sheet'!Z25-'Balance Sheet'!AA25) | AB38: =-('Balance Sheet'!AA25-'Balance Sheet'!AB25) | AC38: =-('Balance Sheet'!Z25-'Balance Sheet'!AC25) | AD38: =-('Balance Sheet'!AC25-'Balance Sheet'!AD25) | AE38: =-('Balance Sheet'!AD25-'Balance Sheet'!AE25) | AF38: =-('Balance Sheet'!AC25-'Balance Sheet'!AF25) | AG38: =-('Balance Sheet'!AF25-'Balance Sheet'!AG25) | AH38: =-('Balance Sheet'!AG25-'Balance Sheet'!AH25) | AI38: =-('Balance Sheet'!AF25-'Balance Sheet'!AI25)
B39: Net Changes in Working Capital | C39: =SUM(C31:C38) | D39: =SUM(D31:D38) | E39: -6.1146 | F39: =SUM(F31:F38) | G39: =SUM(G31:G38) | H39: -14.0028 | I39: =SUM(I31:I38) | J39: =SUM(J31:J38) | K39: -39.8298 | L39: =SUM(L31:L38) | M39: =SUM(M31:M38) | N39: 44.9546 | O39: =SUM(O31:O38) | P39: =SUM(P31:P38) | Q39: =SUM(Q31:Q38) | R39: =SUM(R31:R38) | S39: =SUM(S31:S38) | T39: =SUM(T31:T38) | U39: =SUM(U31:U38) | V39: =SUM(V31:V38) | ... AI39: =SUM(AI31:AI38)
B40: Cash Generated from Operations | C40: =C29+C39 | D40: =D29+D39 | E40: 65.2755 | F40: =F29+F39 | G40: =G29+G39 | H40: 58.3378 | I40: =I29+I39 | J40: =J29+J39 | K40: 43.1296 | L40: =L29+L39 | M40: =M29+M39 | N40: =N29+N39 | O40: =O29+O39 | P40: =P29+P39 | Q40: =Q29+Q39 | R40: =R29+R39 | S40: =S29+S39 | ... AI40: =AI29+AI39
B41: Direct Taxes paid (Net of Tax refund) | C41: -4.6335 | D41: =E41-C41 | E41: -12.2944 | F41: -4.2634 | G41: =H41-F41 | H41: 15.7049 | I41: -6.1715 | J41: =K41-I41 | K41: -13.1125 | L41: -8.94401 | M41: =N41-L41 | N41: -10.0262 | O41: -12.8494 | P41: =Q41-O41 | Q41: -28.2461 | R41: -13.7643 | S41: =T41-R41 | T41: -30.6684 | U41: =-'Income Statement'!U41+('Balance Sheet'!U27-'Balance Sheet'!T27)+('Balance Sheet'!T52-'Balance Sheet'!U52) | V41: =-'Income Statement'!V41+('Balance Sheet'!V27-'Balance Sheet'!U27)+('Balance Sheet'!U52-'Balance Sheet'!V52) | W41: =U41+V41 | X41: =-'Income Statement'!X41+('Balance Sheet'!X27-'Balance Sheet'!W27)+('Balance Sheet'!W52-'Balance Sheet'!X52) | Y41: =-'Income Statement'!Y41+('Balance Sheet'!Y27-'Balance Sheet'!X27)+('Balance Sheet'!X52-'Balance Sheet'!Y52) | Z41: =-'Income Statement'!Z41 | AA41: =-'Income Statement'!AA41+('Balance Sheet'!AA27-'Balance Sheet'!Z27)+('Balance Sheet'!Z52-'Balance Sheet'!AA52) | AB41: =-'Income Statement'!AB41+('Balance Sheet'!AB27-'Balance Sheet'!AA27)+('Balance Sheet'!AA52-'Balance Sheet'!AB52) | AC41: =-'Income Statement'!AC41 | AD41: =-'Income Statement'!AD41+('Balance Sheet'!AD27-'Balance Sheet'!AC27)+('Balance Sheet'!AC52-'Balance Sheet'!AD52) | AE41: =-'Income Statement'!AE41+('Balance Sheet'!AE27-'Balance Sheet'!AD27)+('Balance Sheet'!AD52-'Balance Sheet'!AE52) | AF41: =-'Income Statement'!AF41 | AG41: =-'Income Statement'!AG41+('Balance Sheet'!AG27-'Balance Sheet'!AF27)+('Balance Sheet'!AF52-'Balance Sheet'!AG52) | AH41: =-'Income Statement'!AH41+('Balance Sheet'!AH27-'Balance Sheet'!AG27)+('Balance Sheet'!AG52-'Balance Sheet'!AH52) | AI41: =-'Income Statement'!AI41
B42: Net Cash Flow from Operating Activities | C42: =SUM(C40:C41) | D42: =SUM(D40:D41) | E42: =SUM(E40:E41) | F42: =SUM(F40:F41) | G42: =SUM(G40:G41) | H42: =SUM(H40:H41) | I42: =SUM(I40:I41) | J42: =SUM(J40:J41) | ... AI42: =SUM(AI40:AI41)
B43: check | C43: 66.134 | E43: 52.9811 | F43: 43.4005 | H43: 74.0427 | I43: 27.5785 | K43: 30.0171 | L43: 95.67259 | N43: 169.3843 | O43: -15.8562 | Q43: -7.1533 | R43: -62.1927 | T43: 2.1621
...

Sheet Graphical Representation
B1: Anup Engineering Limited
B2: Fiscal year ending 31st Mar, 2026
B3: All amounts in ₹ crores except per share data
B5: GRAPHICAL REPRESENTATION
B154: Key Financials
B155: Year | C155: H1 | D155: H2 | E155: FY21 | F155: H1 | G155: H2 | H155: FY22 | I155: H1 | J155: H2 | K155: FY23 | L155: H1 | M155: H2 | N155: FY24 | O155: H1 | P155: H2 | Q155: FY25 | R155: H1 | S155: H2 | T155: FY26 | U155: H1 | V155: H2 | W155: FY27 E | X155: H1 | Y155: H2 | Z155: FY28 E | AA155: H1 | AB155: H2 | AC155: FY29 E | AD155: H1 | AE155: H2 | AF155: FY30 E | AG155: H1 | AH155: H2 | AI155: FY31 E
C156: 2021 | D156: 2021 | F156: 2022 | G156: 2022 | I156: 2023 | J156: 2023 | L156: 2024 | M156: 2024 | O156: 2025 | P156: 2025 | R156: 2026 | S156: 2026 | U156: 2027 E | V156: 2027 E | X156: 2028 E | Y156: 2028 E | AA156: 2029 E | AB156: 2029 E | AD156: 2030 E | AE156: 2030 E | AG156: 2031 E | AH156: 2031 E
B157: Revenue from operations | C157: ='Income Statement'!C8 | D157: ='Income Statement'!D8 | E157: ='Income Statement'!E8 | F157: ='Income Statement'!F8 | G157: ='Income Statement'!G8 | H157: ='Income Statement'!H8 | I157: ='Income Statement'!I8 | J157: ='Income Statement'!J8 | ... AI157: ='Income Statement'!AI8
B158: Growth % | F158: =(F157-C157)/C157 | G158: =(G157-D157)/D157 | H158: =(H157-E157)/E157 | I158: =(I157-F157)/F157 | J158: =(J157-G157)/G157 | K158: =(K157-H157)/H157 | L158: =(L157-I157)/I157 | M158: =(M157-J157)/J157 | ... AI158: =(AI157-AF157)/AF157
B160: Segment Wise Revenue Execution
B161: Heat Exchangers | C161: ='Revenue Segments'!C14 | D161: ='Revenue Segments'!D14 | E161: ='Revenue Segments'!E14 | F161: ='Revenue Segments'!F14 | G161: ='Revenue Segments'!G14 | H161: ='Revenue Segments'!H14 | I161: ='Revenue Segments'!I14 | J161: ='Revenue Segments'!J14 | ... AI161: ='Revenue Segments'!AI14
B162: as % of Revenue | E162: =E161/E$157 | F162: =F161/F$157 | G162: =G161/G$157 | H162: =H161/H$157 | I162: =I161/I$157 | J162: =J161/J$157 | K162: =K161/K$157 | L162: =L161/L$157 | ... AI162: =AI161/AI$157
B163: Vessels | C163: ='Revenue Segments'!C26 | D163: ='Revenue Segments'!D26 | E163: ='Revenue Segments'!E26 | F163: ='Revenue Segments'!F26 | G163: ='Revenue Segments'!G26 | H163: ='Revenue Segments'!H26 | I163: ='Revenue Segments'!I26 | J163: ='Revenue Segments'!J26 | ... AI163: ='Revenue Segments'!AI26
B164: as % of Revenue | E164: =E163/E$157 | F164: =F163/F$157 | G164: =G163/G$157 | H164: =H163/H$157 | I164: =I163/I$157 | J164: =J163/J$157 | K164: =K163/K$157 | L164: =L163/L$157 | ... AI164: =AI163/AI$157
B165: Towers & Reactors | C165: ='Revenue Segments'!C38 | D165: ='Revenue Segments'!D38 | E165: ='Revenue Segments'!E38 | F165: ='Revenue Segments'!F38 | G165: ='Revenue Segments'!G38 | H165: ='Revenue Segments'!H38 | I165: ='Revenue Segments'!I38 | J165: ='Revenue Segments'!J38 | ... AI165: ='Revenue Segments'!AI38
B166: as % of Revenue | E166: =E165/E$157 | F166: =F165/F$157 | G166: =G165/G$157 | H166: =H165/H$157 | I166: =I165/I$157 | J166: =J165/J$157 | K166: =K165/K$157 | L166: =L165/L$157 | ... AI166: =AI165/AI$157
B167: Tank & Silos | C167: ='Revenue Segments'!C50 | D167: ='Revenue Segments'!D50 | E167: ='Revenue Segments'!E50 | F167: ='Revenue Segments'!F50 | G167: ='Revenue Segments'!G50 | H167: ='Revenue Segments'!H50 | I167: ='Revenue Segments'!I50 | J167: ='Revenue Segments'!J50 | ... AI167: ='Revenue Segments'!AI50
B168: as % of Revenue | E168: =E167/E$157 | F168: =F167/F$157 | G168: =G167/G$157 | H168: =H167/H$157 | I168: =I167/I$157 | J168: =J167/J$157 | K168: =K167/K$157 | L168: =L167/L$157 | ... AI168: =AI167/AI$157
B169: Centrifuge & Others | C169: ='Revenue Segments'!C62 | D169: ='Revenue Segments'!D62 | E169: ='Revenue Segments'!E62 | F169: ='Revenue Segments'!F62 | G169: ='Revenue Segments'!G62 | H169: ='Revenue Segments'!H62 | I169: ='Revenue Segments'!I62 | J169: ='Revenue Segments'!J62 | ... AI169: ='Revenue Segments'!AI62
B170: as % of Revenue | E170: =E169/E$157 | F170: =F169/F$157 | G170: =G169/G$157 | H170: =H169/H$157 | I170: =I169/I$157 | J170: =J169/J$157 | K170: =K169/K$157 | L170: =L169/L$157 | ... AI170: =AI169/AI$157
B172: Order Book | C172: ='Revenue Segments'!C68 | D172: ='Revenue Segments'!D68 | E172: ='Revenue Segments'!E68 | F172: ='Revenue Segments'!F68 | G172: ='Revenue Segments'!G68 | H172: ='Revenue Segments'!H68 | I172: ='Revenue Segments'!I68 | J172: ='Revenue Segments'!J68 | ... AI172: ='Revenue Segments'!AI68
B173: Order Inflow | C173: ='Revenue Segments'!C11+'Revenue Segments'!C23+'Revenue Segments'!C35+'Revenue Segments'!C47+'Revenue Segments'!C59 | D173: ='Revenue Segments'!D11+'Revenue Segments'!D23+'Revenue Segments'!D35+'Revenue Segments'!D47+'Revenue Segments'!D59 | E173: ='Revenue Segments'!E11+'Revenue Segments'!E23+'Revenue Segments'!E35+'Revenue Segments'!E47+'Revenue Segments'!E59 | F173: ='Revenue Segments'!F11+'Revenue Segments'!F23+'Revenue Segments'!F35+'Revenue Segments'!F47+'Revenue Segments'!F59 | G173: ='Revenue Segments'!G11+'Revenue Segments'!G23+'Revenue Segments'!G35+'Revenue Segments'!G47+'Revenue Segments'!G59 | H173: ='Revenue Segments'!H11+'Revenue Segments'!H23+'Revenue Segments'!H35+'Revenue Segments'!H47+'Revenue Segments'!H59 | I173: ='Revenue Segments'!I11+'Revenue Segments'!I23+'Revenue Segments'!I35+'Revenue Segments'!I47+'Revenue Segments'!I59 | J173: ='Revenue Segments'!J11+'Revenue Segments'!J23+'Revenue Segments'!J35+'Revenue Segments'!J47+'Revenue Segments'!J59 | ... AI173: ='Revenue Segments'!AI11+'Revenue Segments'!AI23+'Revenue Segments'!AI35+'Revenue Segments'!AI47+'Revenue Segments'!AI59
B174: Order Book to Bill Ratio | C174: =C172/C157 | D174: =D172/D157 | E174: =E172/E157 | F174: =F172/F157 | G174: =G172/G157 | H174: =H172/H157 | I174: =I172/I157 | J174: =J172/J157 | ... AI174: =AI172/AI157
B175: Book to Bill Ratio | E175: =E173/E157 | F175: =F173/F157 | G175: =G173/G157 | H175: =H173/H157 | I175: =I173/I157 | J175: =J173/J157 | K175: =K173/K157 | L175: =L173/L157 | ... AI175: =AI173/AI157
B177: EBITDA | C177: ='Income Statement'!C23 | D177: ='Income Statement'!D23 | E177: ='Income Statement'!E23 | F177: ='Income Statement'!F23 | G177: ='Income Statement'!G23 | H177: ='Income Statement'!H23 | I177: ='Income Statement'!I23 | J177: ='Income Statement'!J23 | ... AI177: ='Income Statement'!AI23
B178: EBITDA Margin | C178: ='Income Statement'!C24 | D178: ='Income Statement'!D24 | E178: ='Income Statement'!E24 | F178: ='Income Statement'!F24 | G178: ='Income Statement'!G24 | H178: ='Income Statement'!H24 | I178: ='Income Statement'!I24 | J178: ='Income Statement'!J24 | ... AI178: ='Income Statement'!AI24
B180: EBIT | C180: ='Income Statement'!C27 | D180: ='Income Statement'!D27 | E180: ='Income Statement'!E27 | F180: ='Income Statement'!F27 | G180: ='Income Statement'!G27 | H180: ='Income Statement'!H27 | I180: ='Income Statement'!I27 | J180: ='Income Statement'!J27 | ... AI180: ='Income Statement'!AI27
B181: EBIT Margin | C181: ='Income Statement'!C28 | D181: ='Income Statement'!D28 | E181: ='Income Statement'!E28 | F181: ='Income Statement'!F28 | G181: ='Income Statement'!G28 | H181: ='Income Statement'!H28 | I181: ='Income Statement'!I28 | J181: ='Income Statement'!J28 | ... AI181: ='Income Statement'!AI28
B183: PAT | C183: ='Income Statement'!C43 | D183: ='Income Statement'!D43 | E183: ='Income Statement'!E43 | F183: ='Income Statement'!F43 | G183: ='Income Statement'!G43 | H183: ='Income Statement'!H43 | I183: ='Income Statement'!I43 | J183: ='Income Statement'!J43 | ... AI183: ='Income Statement'!AI43
B184: PAT Margin | C184: ='Income Statement'!C46 | D184: ='Income Statement'!D46 | E184: ='Income Statement'!E46 | F184: ='Income Statement'!F46 | G184: ='Income Statement'!G46 | H184: ='Income Statement'!H46 | I184: ='Income Statement'!I46 | J184: ='Income Statement'!J46 | ... AI184: ='Income Statement'!AI46
B186: EPS | C186: ='Income Statement'!C49 | D186: ='Income Statement'!D49 | E186: ='Income Statement'!E49 | F186: ='Income Statement'!F49 | G186: ='Income Statement'!G49 | H186: ='Income Statement'!H49 | I186: ='Income Statement'!I49 | J186: ='Income Statement'!J49 | ... AI186: ='Income Statement'!AI49
